Workbook

Sheet Quote Input
A1: CWDB Deck Project Quote
A2: Sell Price | C2: =E40
A3: Range (low - high) | C3: =TEXT(E41,"$#,##0")&" - "&TEXT(E42,"$#,##0")
A4: Sell Price / SF | C4: =IFERROR(E43, 0)
A6: Project Info | D6: Cost Components
A7: Client Name | B7: Thomas Quinn | D7: Framing $/SF | E7: =IFERROR(INDEX('Pricing DB'!$B$35:$B$36, MATCH(B23, 'Pricing DB'!$A$35:$A$36, 0)), 0)
A8: Project Address | B8: 10186 County Road Mm, 54407 | D8: Decking $/SF | E8: =IFERROR(INDEX('Pricing DB'!$B$7:$B$19, MATCH(B21, 'Pricing DB'!$A$7:$A$19, 0)), 0)
A9: Estimator | B9: James Slogar | D9: Decking Waste % | E9: =IFERROR(INDEX('Pricing DB'!$D$7:$D$19, MATCH(B21, 'Pricing DB'!$A$7:$A$19, 0)), 0)
A10: Quote Date | B10: 2026-06-18 | D10: Railing $/LF | E10: =IFERROR(INDEX('Pricing DB'!$B$23:$B$31, MATCH(B22, 'Pricing DB'!$A$23:$A$31, 0)), 0)
A12: Project Type | D12: Multipliers
A13: Project Type | B13: Full Tear-Out + New Build | D13: Height multiplier | E13: =IFERROR(INDEX('Pricing DB'!$B$64:$B$65, MATCH(B26, 'Pricing DB'!$A$64:$A$65, 0)), 1)
D14: Grade multiplier | E14: =IFERROR(INDEX('Pricing DB'!$B$68:$B$70, MATCH(B27, 'Pricing DB'!$A$68:$A$70, 0)), 1)
A15: Dimensions | D15: Complexity multiplier | E15: =IFERROR(INDEX('Pricing DB'!$B$73:$B$75, MATCH(B28, 'Pricing DB'!$A$73:$A$75, 0)), 1)
A16: Deck Length | B16: 16 | C16: feet | D16: Market multiplier | E16: =IFERROR(INDEX('Pricing DB'!$B$78:$B$80, MATCH(B29, 'Pricing DB'!$A$78:$A$80, 0)), 1)
A17: Deck Depth | B17: 8 | C17: feet | D17: Combined multiplier | E17: =IF(INDEX('Project Type Behavior'!$I$4:$I$10, MATCH(B13, 'Project Type Behavior'!$A$4:$A$10, 0))="N", 1, IF(INDEX('Project Type Behavior'!$I$4:$I$10, MATCH(B13, 'Project Type Behavior'!$A$4:$A$10, 0))="Light", E13*E14, E13*E14*E15*E16))
A18: Deck SF (calc) | B18: =B16*B17 | C18: sq ft
D19: Line Items
A20: Materials | D20: Base Package | E20: =B18*(IF(INDEX('Project Type Behavior'!$C$4:$C$10, MATCH(B13, 'Project Type Behavior'!$A$4:$A$10, 0))="Y", E7, 0) + IF(INDEX('Project Type Behavior'!$D$4:$D$10, MATCH(B13, 'Project Type Behavior'!$A$4:$A$10, 0))="Y", E8*(1+E9), 0))*E17
A21: Decking Material | B21: Pressure-Treated Pine | D21: Demo | E21: =IF(INDEX('Project Type Behavior'!$B$4:$B$10, MATCH(B13, 'Project Type Behavior'!$A$4:$A$10, 0))="N", 0, B18*IFERROR(INDEX('Pricing DB'!$B$40:$B$46, MATCH(B13, 'Pricing DB'!$A$40:$A$46, 0)), 0))
A22: Railing Material | B22: Pressure-Treated Wood Rail | D22: Border | E22: =IF(INDEX('Project Type Behavior'!$D$4:$D$10, MATCH(B13, 'Project Type Behavior'!$A$4:$A$10, 0))<>"Y", 0, IF(B32="Double Border", B18*'Pricing DB'!$B$91, 0))
A23: Framing Material | B23: KDAT Pressure-Treated | D23: Railing | E23: =IF(OR(INDEX('Project Type Behavior'!$E$4:$E$10, MATCH(B13, 'Project Type Behavior'!$A$4:$A$10, 0))="N"), 0, B33*E10)
D24: Fascia | E24: =IF(INDEX('Project Type Behavior'!$D$4:$D$10, MATCH(B13, 'Project Type Behavior'!$A$4:$A$10, 0))<>"Y", 0, B34*'Pricing DB'!$B$94)
A25: Site Conditions | D25: Stairs | E25: =IF(OR(INDEX('Project Type Behavior'!$F$4:$F$10, MATCH(B13, 'Project Type Behavior'!$A$4:$A$10, 0))="N", B35=0), 0, 'Pricing DB'!$B$83 + B36*'Pricing DB'!$B$84 + B37*'Pricing DB'!$B$85 + IF(B38="Yes", 'Pricing DB'!$B$86, 0) + IF(B32="Double Border", B36*'Pricing DB'!$B$87, 0))
A26: Height | B26: 1 Story / Low | D26: Stain | E26: =IF(INDEX('Project Type Behavior'!$H$4:$H$10, MATCH(B13, 'Project Type Behavior'!$A$4:$A$10, 0))<>"Y", 0, B41*IFERROR(INDEX('Pricing DB'!$C$50:$C$55, MATCH(B42&"|"&B43, 'Pricing DB'!$D$50:$D$55, 0)), 0))
A27: Grade | B27: Flat / Normal Access | D27: Repairs | E27: =IF(AND(B13<>"Stain + Minor Repairs", B13<>"Resurface (Boards Only)"), 0, B46*'Pricing DB'!$B$58 + B47*'Pricing DB'!$B$59 + IF(B48="Yes", 'Pricing DB'!$B$60, 0) + IF(B13="Resurface (Boards Only)", 'Pricing DB'!$B$61, 0))
A28: Complexity | B28: Simple Rectangle | D28: Skirting / Privacy Wall | E28: =IF(INDEX('Project Type Behavior'!$D$4:$D$10, MATCH(B13, 'Project Type Behavior'!$A$4:$A$10, 0))<>"Y", 0, B51*'Pricing DB'!$B$95)
A29: Market Load | B29: Normal Schedule | D29: Lighting Fixtures | E29: =B52*IFERROR(INDEX('Pricing DB'!$C$99:$C$103, MATCH("lighting", 'Pricing DB'!$D$99:$D$103, 0)), 0)
D30: Built-In Benches | E30: =B53*IFERROR(INDEX('Pricing DB'!$C$99:$C$103, MATCH("bench", 'Pricing DB'!$D$99:$D$103, 0)), 0)
A31: Scope Detail | D31: Privacy Screen | E31: =B54*IFERROR(INDEX('Pricing DB'!$C$99:$C$103, MATCH("privacy_screen", 'Pricing DB'!$D$99:$D$103, 0)), 0)
A32: Border Style | B32: Pencil Border | D32: Hot Tub Structural | E32: =IF(B55="Yes", IFERROR(INDEX('Pricing DB'!$C$99:$C$103, MATCH("hot_tub", 'Pricing DB'!$D$99:$D$103, 0)), 0), 0)
A33: Railing LF | B33: 32 | C33: linear ft | D33: Permit / Engineering | E33: =B58
A34: Fascia LF | B34: 0 | C34: linear ft | D34: Dumpster / Cleanup | E34: =B59
A35: Stair Runs | B35: 1 | C35: number of stair runs | D35: Mobilization | E35: =B60
A36: Stair Treads | B36: 3 | C36: total treads | D36: Misc | E36: =B61
A37: Stair Landings | B37: 0 | C37: number of landings | D37: SUBTOTAL (Cost) | E37: =IF(B13="Fence", E50, SUM(E20:E36))
A38: Wraparound Stair | B38: No
D39: Final Price
A40: Stain Inputs (only used if project type involves staining) | D40: Sell Price | E40: =E37/(1-B64)
A41: Stain SF | B41: 0 | C41: SF of surface to stain | D41: Low Range | E41: =E40*(1-B65)
A42: Stain Type | B42: Solid / Paint-and-Sealer | D42: High Range | E42: =E40*(1+B65)
...

Sheet Pricing DB
A1: CWDB Pricing Database
A2: As-of 2026-05-28 · Edit yellow cells. Regenerate workbook to reflect changes. Review quarterly.
A5: Decking Materials
A6: Name | B6: Sell $/SF | C6: Material $/SF | D6: Waste % | E6: Description | F6: Source
A7: Pressure-Treated Pine | B7: 4.5 | C7: 1.25 | D7: 0.1 | E7: Budget tier. AC2 5/4x6x16 PT decking (Menards SKU 1110669). 8-12 yr life with stain maintenance. | F7: Menards Wausau 2026-05 (fallback - verify in-person)
A8: Cedar | B8: 12 | C8: 4.85 | D8: 0.1 | E8: Mid wood tier. Red Cedar 5/4x6x16 (Menards SKU 1072723 - $35.59 rebate). Natural rot resistance. 15-20 yr life. | F8: Menards Wausau 2026-05 (confirmed)
A9: Trex Enhance | B9: 22 | C9: 7.5 | D9: 0.08 | E9: Entry composite. 25-yr warranty. Budget-friendly composite option. | F9: John Garcia spreadsheet (verified 2026-05)
A10: Trex Select | B10: 30 | C10: 10.5 | D10: 0.08 | E10: Mid-tier composite. 35-yr warranty. Most common composite upgrade. | F10: John Garcia spreadsheet (verified 2026-05)
A11: Trex Transcend | B11: 42 | C11: 16 | D11: 0.1 | E11: Premium composite. Full grain, deep colors. 50-yr warranty. | F11: John Garcia spreadsheet (verified 2026-05)
A12: TimberTech AZEK Harvest | B12: 33 | C12: 11.92 | D12: 0.08 | E12: Advanced PVC (AZEK), Harvest Collection - refined cathedral grain. Capped polymer, no organic content. Entry AZEK tier. | F12: John Garcia / Badger cost sheet 2026-06 ($5.47/LF). sell = 5.47x2.18x2.75. CONFIRM markup.
A13: TimberTech AZEK Harvest+ | B13: 41 | C13: 14.91 | D13: 0.08 | E13: Advanced PVC (AZEK), Harvest+ Collection - understated cathedral grain. | F13: John Garcia / Badger cost sheet 2026-06 ($6.84/LF). sell = 6.84x2.18x2.75. CONFIRM markup + colors.
A14: TimberTech AZEK Landmark | B14: 41 | C14: 14.91 | D14: 0.08 | E14: Advanced PVC (AZEK), Landmark Collection - crosscut hardwoods, cathedral grain. | F14: John Garcia / Badger cost sheet 2026-06 ($6.84/LF). sell = 6.84x2.18x2.75. CONFIRM markup.
A15: TimberTech AZEK Vintage | B15: 47 | C15: 17.24 | D15: 0.08 | E15: Advanced PVC (AZEK), Vintage Collection - exotic hardwoods, wire-brushed finish. Top AZEK tier. | F15: John Garcia / Badger cost sheet 2026-06 ($7.91/LF). sell = 7.91x2.18x2.75. CONFIRM markup.
A16: TimberTech PRO Terrain | B16: 27 | C16: 9.81 | D16: 0.08 | E16: Capped composite (PRO), Terrain Collection - rugged cathedral grain. Entry PRO tier. | F16: John Garcia / Woodland cost sheet 2026-06 ($4.50/LF). sell = 4.50x2.18x2.75. CONFIRM markup.
A17: TimberTech PRO Terrain+ | B17: 27 | C17: 9.81 | D17: 0.08 | E17: Capped composite (PRO), Terrain+ Collection - subtle wood grain. | F17: John Garcia / Woodland cost sheet 2026-06 ($4.50/LF). sell = 4.50x2.18x2.75. CONFIRM markup + colors.
A18: TimberTech PRO Reserve | B18: 38 | C18: 13.93 | D18: 0.08 | E18: Capped composite (PRO), Reserve Collection - reclaimed-wood look. | F18: John Garcia / Woodland cost sheet 2026-06 ($6.39/LF). sell = 6.39x2.18x2.75. CONFIRM markup.
A19: TimberTech PRO Legacy | B19: 46 | C19: 16.74 | D19: 0.08 | E19: Capped composite (PRO), Legacy Collection - hand-scraped finish. Top PRO tier. | F19: John Garcia / Woodland cost sheet 2026-06 ($7.68/LF). sell = 7.68x2.18x2.75. CONFIRM markup.
A21: Railing Materials
A22: Name | B22: Sell $/LF | C22: Material $/LF | D22: Description | E22: Source
A23: Pressure-Treated Wood Rail | B23: 40 | C23: 11 | D23: PT 2x4 top/bottom rail (Menards SKU 1110818) with PT 2x2 balusters and 4x4 posts. Budget tier. | E23: Menards Wausau 2026-05 (confirmed for 2x4)
A24: Cedar Wood Rail | B24: 60 | C24: 18 | D24: Cedar 2x4 top/bottom rail (Menards SKU 1072752 - fallback) with cedar balusters. Mid wood tier. | E24: Menards Wausau 2026-05 (fallback - verify in-person)
A25: Trex Aluminum | B25: 165 | C25: 65 | D25: Trex Signature aluminum rail system. Black/bronze. Lifetime warranty. | E25: John Garcia spreadsheet (verified 2026-05)
A26: Cable Railing | B26: 110 | C26: 45 | D26: Feeney CableRail (Menards SKU 6310-PKG) on PT/cedar posts. Full system with top+bot rail. Modern look, view preservation. | E26: Dunn Lumber + Menards 2026-05 (corroborated)
A27: Glass Panel | B27: 275 | C27: 180 | D27: Tempered glass panel railing with aluminum posts. Premium tier - $60K+ projects only. | E27: Angi + HomeGuide + Viewrail (industry avg 2026-05)
A28: TimberTech Reliance Rail (Vinyl) | B28: 70 | C28: 28 | D28: Premium vinyl railing, value tier. Low-maintenance. CONFIRM pricing. | E28: Market research 2026-06 (TimberTech does not publish; rail material ~$20-60/LF). sell = material x 2.5. CONFIRM.
A29: TimberTech Premier Rail (Composite) | B29: 100 | C29: 40 | D29: Composite railing, mid tier. Pairs with PRO/EDGE decking. | E29: Market research 2026-06. sell = material x 2.5. CONFIRM.
A30: TimberTech Impression Rail Express (Aluminum) | B30: 110 | C30: 45 | D30: Powder-coated aluminum railing, mid tier. Slim sightlines. | E30: Market research 2026-06. sell = material x 2.5. CONFIRM.
A31: TimberTech RadianceRail (Premium) | B31: 150 | C31: 60 | D31: Premium capped composite/PVC railing, drink-rail capable. Top TimberTech rail tier. | E31: Market research 2026-06. sell = material x 2.5. CONFIRM.
A33: Framing Materials
A34: Name | B34: Sell $/SF | C34: Material $/SF | D34: Description | E34: Source
A35: KDAT Pressure-Treated | B35: 38 | C35: 12 | D35: Kiln-dried-after-treatment PT lumber. Code-compliant for ground contact. CWDB standard. | E35: John Garcia spreadsheet (verified 2026-05)
A36: Steel (Fortress Evolution) | B36: 52 | C36: 28 | D36: Galvanized steel deck framing. Premium tier - rare residential WI. Sell on warranty + fire resistance + no rot. Special order through Fortress dealer. | E36: HomeAdvisor + Fortress BP 2026-05 (industry avg)
A38: Demo Rates by Project Type
A39: Project Type | B39: Demo $/SF
A40: Stain Only | B40: 0
A41: Stain + Minor Repairs | B41: 0
A42: Resurface (Boards Only) | B42: 3
A43: Frame + Deck Rebuild (Keep Footings) | B43: 6
A44: Full Tear-Out + New Build | B44: 8
A45: New Build (No Tear-Out) | B45: 0
...

Sheet Project Type Behavior
A1: Project Type Behavior Matrix
A2: Read-only. Each project type tells the engine which cost buckets to include (Y), exclude (N), allow optionally (OPT), or inspect only. Multipliers: Y = all four, Light = Height + Grade only, N = none.
A3: Project Type | B3: Demo | C3: Frame | D3: Deck | E3: Rail | F3: Stair | G3: Footing | H3: Stain | I3: Multipliers | J3: Description
A4: Stain Only | B4: N | C4: N | D4: N | E4: N | F4: N | G4: N | H4: Y | I4: N | J4: Refinish-only job. Wash, sand, set fasteners, stain. No structural work.
A5: Stain + Minor Repairs | B5: N | C5: N | D5: N | E5: N | F5: N | G5: N | H5: Y | I5: Light | J5: Stain plus targeted repairs - board swap, joist sister, hardware. Use Repair Bucket for repair scope. For new rail/stair systems, use Resurface or Frame Rebuild.
A6: Resurface (Boards Only) | B6: Y | C6: Inspect | D6: Y | E6: OPT | F6: OPT | G6: N | H6: N | I6: Y | J6: Pull old boards, inspect frame, install new boards. Optional railing + stair refresh - zero out Railing LF / Stair Runs if not in scope.
A7: Frame + Deck Rebuild (Keep Footings) | B7: Y | C7: Y | D7: Y | E7: Y | F7: Y | G7: N | H7: N | I7: Y | J7: Tear out frame and deck down to footings. Build new frame + deck + rails + stairs. Reuse footings.
A8: Full Tear-Out + New Build | B8: Y | C8: Y | D8: Y | E8: Y | F8: Y | G8: Y | H8: N | I8: Y | J8: Complete demolition including footings. New build from grade up.
A9: New Build (No Tear-Out) | B9: N | C9: Y | D9: Y | E9: Y | F9: Y | G9: Y | H9: N | I9: Y | J9: Brand-new deck where none existed. New footings, framing, decking, rails, stairs. No demolition, tear-out, or waste-removal cost.
A10: Fence | B10: N | C10: N | D10: N | E10: N | F10: N | G10: N | H10: N | I10: N | J10: Fence build, priced by linear foot. Uses fence_materials (rate by height) + gates + tear-out, not the deck SF model.

Sheet Materials List
A1: Preliminary Materials List
A2: Shopping list driven by Quote Input. Quantities update live. Edit unit costs in Pricing DB > Materials Unit Costs section. Total at bottom is materials only - labor and margin live in the Quote.
A4: Project Type: | B4: ='Quote Input'!B13
A5: Dimensions: | B5: ='Quote Input'!B16&" ft x "&'Quote Input'!B17&" ft = "&'Quote Input'!B18&" SF deck"
A6: Materials selected: | B6: ="Decking: "&'Quote Input'!B21&" | Railing: "&'Quote Input'!B22&" | Framing: "&'Quote Input'!B23
A8: Decking
A9: Item | B9: Qty | C9: Unit | D9: Unit Cost | E9: Line Cost | F9: Notes
A10: ="Deck board: "&'Quote Input'!B21&" (5/4x6x16)" | B10: =IF(INDEX('Project Type Behavior'!$D$4:$D$10, MATCH('Quote Input'!B13, 'Project Type Behavior'!$A$4:$A$10, 0))="Y", CEILING('Quote Input'!B18*(1+'Quote Input'!E9)/7.33, 1), 0) | C10: each | D10: =IFERROR(INDEX('Pricing DB'!$C$7:$C$19, MATCH('Quote Input'!B21, 'Pricing DB'!$A$7:$A$19, 0))*7.33, 0) | E10: =B10*D10 | F10: 5/4x6x16 nominal = 5.5" face x 16 ft = 7.33 SF/board
A11: =IF(LEFT('Quote Input'!B21,4)="Trex", "Hidden fasteners (composite) - 50 ct box", "3-inch stainless deck screws - 5 lb box") | B11: =IF(INDEX('Project Type Behavior'!$D$4:$D$10, MATCH('Quote Input'!B13, 'Project Type Behavior'!$A$4:$A$10, 0))<>"Y", 0, IF(LEFT('Quote Input'!B21,4)="Trex", CEILING('Quote Input'!B18/25, 1), CEILING('Quote Input'!B18/100, 1))) | C11: box | D11: =IF(LEFT('Quote Input'!B21,4)="Trex", INDEX('Pricing DB'!$D$140:$D$167, MATCH("hidden_fastener_box", 'Pricing DB'!$A$140:$A$167, 0)), INDEX('Pricing DB'!$D$140:$D$167, MATCH("deck_screw_box_5lb", 'Pricing DB'!$A$140:$A$167, 0))) | E11: =B11*D11 | F11: Composite: ~1 box / 25 SF. Wood deck: ~1 box (5 lb) per 100 SF
A12: ="Fascia board: "&'Quote Input'!B21&" (16 ft)" | B12: =IF(INDEX('Project Type Behavior'!$D$4:$D$10, MATCH('Quote Input'!B13, 'Project Type Behavior'!$A$4:$A$10, 0))<>"Y", 0, CEILING('Quote Input'!B34/16, 1)) | C12: each | D12: =IFERROR(INDEX('Pricing DB'!$C$7:$C$19, MATCH('Quote Input'!B21, 'Pricing DB'!$A$7:$A$19, 0))*7.33, 0) | E12: =B12*D12 | F12: Use matching deck material on exposed rim and stair stringers
A13: Construction adhesive (PL Premium 10 oz) | B13: =IF(INDEX('Project Type Behavior'!$D$4:$D$10, MATCH('Quote Input'!B13, 'Project Type Behavior'!$A$4:$A$10, 0))<>"Y", 0, CEILING('Quote Input'!B18/100, 1)) | C13: tube | D13: =INDEX('Pricing DB'!$D$140:$D$167, MATCH("construction_adhesive", 'Pricing DB'!$A$140:$A$167, 0)) | E13: =B13*D13 | F13: ~1 tube per 100 SF (ledger, stair stringers, beam laminations)
A15: Framing - KDAT Pressure-Treated (rows 17-23 zero out if Steel framing selected; see row 57)
A16: Item | B16: Qty | C16: Unit | D16: Unit Cost | E16: Line Cost | F16: Notes
A17: KDAT PT 2x10x16 (joists, 16" o.c. spacing) | B17: =IF(NOT(AND(INDEX('Project Type Behavior'!$C$4:$C$10, MATCH('Quote Input'!B13, 'Project Type Behavior'!$A$4:$A$10, 0))="Y", 'Quote Input'!B23="KDAT Pressure-Treated")), 0, CEILING('Quote Input'!B16*12/16, 1)+1) | C17: each | D17: =INDEX('Pricing DB'!$D$140:$D$167, MATCH("kdat_2x10x16", 'Pricing DB'!$A$140:$A$167, 0)) | E17: =B17*D17 | F17: One joist every 16 in along the deck length, plus 1 end joist
A18: KDAT PT 2x10x16 (beam, 2-ply) | B18: =IF(NOT(AND(INDEX('Project Type Behavior'!$C$4:$C$10, MATCH('Quote Input'!B13, 'Project Type Behavior'!$A$4:$A$10, 0))="Y", 'Quote Input'!B23="KDAT Pressure-Treated")), 0, 2*CEILING('Quote Input'!B16/16, 1)) | C18: each | D18: =INDEX('Pricing DB'!$D$140:$D$167, MATCH("kdat_2x10x16", 'Pricing DB'!$A$140:$A$167, 0)) | E18: =B18*D18 | F18: 2-ply doubled beam under outer joist ends; lengths cut to span
A19: KDAT PT 2x10x16 (ledger to house) | B19: =IF(NOT(AND(INDEX('Project Type Behavior'!$C$4:$C$10, MATCH('Quote Input'!B13, 'Project Type Behavior'!$A$4:$A$10, 0))="Y", 'Quote Input'!B23="KDAT Pressure-Treated")), 0, CEILING('Quote Input'!B16/16, 1)) | C19: each | D19: =INDEX('Pricing DB'!$D$140:$D$167, MATCH("kdat_2x10x16", 'Pricing DB'!$A$140:$A$167, 0)) | E19: =B19*D19 | F19: Lag-bolted to house rim joist; sealed with flashing
A20: KDAT PT 6x6x8 (beam posts) | B20: =IF(NOT(AND(INDEX('Project Type Behavior'!$C$4:$C$10, MATCH('Quote Input'!B13, 'Project Type Behavior'!$A$4:$A$10, 0))="Y", 'Quote Input'!B23="KDAT Pressure-Treated")), 0, CEILING('Quote Input'!B16/6, 1)+1) | C20: each | D20: =INDEX('Pricing DB'!$D$140:$D$167, MATCH("kdat_6x6x8", 'Pricing DB'!$A$140:$A$167, 0)) | E20: =B20*D20 | F20: Spaced ~6 ft on center along beam; 8-ft length cut to height
A21: Joist hangers (Simpson LUS28 for 2x10) | B21: =IF(NOT(AND(INDEX('Project Type Behavior'!$C$4:$C$10, MATCH('Quote Input'!B13, 'Project Type Behavior'!$A$4:$A$10, 0))="Y", 'Quote Input'!B23="KDAT Pressure-Treated")), 0, CEILING('Quote Input'!B16*12/16, 1)+1) | C21: each | D21: =INDEX('Pricing DB'!$D$140:$D$167, MATCH("joist_hanger_2x10", 'Pricing DB'!$A$140:$A$167, 0)) | E21: =B21*D21 | F21: One per joist at ledger-end and beam-end (count matches joists)
A22: Hurricane ties (Simpson H1) | B22: =IF(NOT(AND(INDEX('Project Type Behavior'!$C$4:$C$10, MATCH('Quote Input'!B13, 'Project Type Behavior'!$A$4:$A$10, 0))="Y", 'Quote Input'!B23="KDAT Pressure-Treated")), 0, CEILING('Quote Input'!B16*12/16, 1)+1) | C22: each | D22: =INDEX('Pricing DB'!$D$140:$D$167, MATCH("hurricane_tie", 'Pricing DB'!$A$140:$A$167, 0)) | E22: =B22*D22 | F22: One per joist where it crosses beam (code-required)
A23: 1/2" x 4" lag screws (ledger to rim) | B23: =IF(NOT(AND(INDEX('Project Type Behavior'!$C$4:$C$10, MATCH('Quote Input'!B13, 'Project Type Behavior'!$A$4:$A$10, 0))="Y", 'Quote Input'!B23="KDAT Pressure-Treated")), 0, CEILING('Quote Input'!B16*12/16, 1)) | C23: each | D23: =INDEX('Pricing DB'!$D$140:$D$167, MATCH("ledger_lag_screw", 'Pricing DB'!$A$140:$A$167, 0)) | E23: =B23*D23 | F23: One every 16" along ledger (Wisconsin code)
A25: Footings (matrix.footing = Y only)
A26: Item | B26: Qty | C26: Unit | D26: Unit Cost | E26: Line Cost | F26: Notes
A27: Concrete tube form 12" x 48" (WI frost line) | B27: =IF(INDEX('Project Type Behavior'!$G$4:$G$10, MATCH('Quote Input'!B13, 'Project Type Behavior'!$A$4:$A$10, 0))<>"Y", 0, (CEILING('Quote Input'!B16/6, 1)+1)) | C27: each | D27: =INDEX('Pricing DB'!$D$140:$D$167, MATCH("concrete_tube_12x48", 'Pricing DB'!$A$140:$A$167, 0)) | E27: =B27*D27 | F27: One tube per post; 48" depth for Wisconsin frost line
A28: Concrete mix 60 lb bag | B28: =IF(INDEX('Project Type Behavior'!$G$4:$G$10, MATCH('Quote Input'!B13, 'Project Type Behavior'!$A$4:$A$10, 0))<>"Y", 0, (CEILING('Quote Input'!B16/6, 1)+1)*4) | C28: bag | D28: =INDEX('Pricing DB'!$D$140:$D$167, MATCH("concrete_bag_60lb", 'Pricing DB'!$A$140:$A$167, 0)) | E28: =B28*D28 | F28: ~4 bags per 12" x 48" tube footing
A29: Rebar 1/2" x 4 ft | B29: =IF(INDEX('Project Type Behavior'!$G$4:$G$10, MATCH('Quote Input'!B13, 'Project Type Behavior'!$A$4:$A$10, 0))<>"Y", 0, (CEILING('Quote Input'!B16/6, 1)+1)*2) | C29: each | D29: =INDEX('Pricing DB'!$D$140:$D$167, MATCH("rebar_half_x_4ft", 'Pricing DB'!$A$140:$A$167, 0)) | E29: =B29*D29 | F29: 2 pieces per footing in cross pattern
A31: Railing
A32: Item | B32: Qty | C32: Unit | D32: Unit Cost | E32: Line Cost | F32: Notes
A33: Trex Signature aluminum rail section (6 ft kit) | B33: =IF(AND(AND(INDEX('Project Type Behavior'!$E$4:$E$10, MATCH('Quote Input'!B13, 'Project Type Behavior'!$A$4:$A$10, 0))<>"N", 'Quote Input'!B33>0), 'Quote Input'!B22="Trex Aluminum"), CEILING('Quote Input'!B33/6, 1), 0) | C33: kit | D33: =INDEX('Pricing DB'!$D$140:$D$167, MATCH("trex_alum_rail_6ft", 'Pricing DB'!$A$140:$A$167, 0)) | E33: =B33*D33 | F33: Includes top/bot rail, balusters; cut to length on site
A34: Trex Signature aluminum post + base kit | B34: =IF(AND(AND(INDEX('Project Type Behavior'!$E$4:$E$10, MATCH('Quote Input'!B13, 'Project Type Behavior'!$A$4:$A$10, 0))<>"N", 'Quote Input'!B33>0), 'Quote Input'!B22="Trex Aluminum"), CEILING('Quote Input'!B33/6, 1)+1, 0) | C34: kit | D34: =INDEX('Pricing DB'!$D$140:$D$167, MATCH("trex_alum_post_kit", 'Pricing DB'!$A$140:$A$167, 0)) | E34: =B34*D34 | F34: One post per 6 ft of railing, plus 1 for the end
A35: =IF('Quote Input'!B22="Pressure-Treated Wood Rail", "AC2 PT 2x4x8 ", IF('Quote Input'!B22="Cedar Wood Rail", "Cedar 2x4x8 ", ""))&"(top + bottom rail)" | B35: =IF(AND(AND(INDEX('Project Type Behavior'!$E$4:$E$10, MATCH('Quote Input'!B13, 'Project Type Behavior'!$A$4:$A$10, 0))<>"N", 'Quote Input'!B33>0), OR('Quote Input'!B22="Pressure-Treated Wood Rail", 'Quote Input'!B22="Cedar Wood Rail")), 2*CEILING('Quote Input'!B33/8, 1), 0) | C35: each | D35: =IF('Quote Input'!B22="Pressure-Treated Wood Rail", INDEX('Pricing DB'!$D$140:$D$167, MATCH("pt_2x4x8", 'Pricing DB'!$A$140:$A$167, 0)), IF('Quote Input'!B22="Cedar Wood Rail", INDEX('Pricing DB'!$D$140:$D$167, MATCH("cedar_2x4x8", 'Pricing DB'!$A$140:$A$167, 0)), 0)) | E35: =B35*D35 | F35: 2 boards (top + bottom) per 8 LF of railing
A36: =IF('Quote Input'!B22="Pressure-Treated Wood Rail", "PT 2x2x42 baluster", IF('Quote Input'!B22="Cedar Wood Rail", "Cedar 2x2x42 baluster", "")) | B36: =IF(AND(AND(INDEX('Project Type Behavior'!$E$4:$E$10, MATCH('Quote Input'!B13, 'Project Type Behavior'!$A$4:$A$10, 0))<>"N", 'Quote Input'!B33>0), OR('Quote Input'!B22="Pressure-Treated Wood Rail", 'Quote Input'!B22="Cedar Wood Rail")), CEILING('Quote Input'!B33*12/4, 1), 0) | C36: each | D36: =IF('Quote Input'!B22="Pressure-Treated Wood Rail", INDEX('Pricing DB'!$D$140:$D$167, MATCH("pt_2x2x42", 'Pricing DB'!$A$140:$A$167, 0)), IF('Quote Input'!B22="Cedar Wood Rail", INDEX('Pricing DB'!$D$140:$D$167, MATCH("cedar_2x2x42", 'Pricing DB'!$A$140:$A$167, 0)), 0)) | E36: =B36*D36 | F36: One baluster every 4 in (code-required spacing)
A37: KDAT PT 4x4x8 (rail posts) | B37: =IF(AND(AND(INDEX('Project Type Behavior'!$E$4:$E$10, MATCH('Quote Input'!B13, 'Project Type Behavior'!$A$4:$A$10, 0))<>"N", 'Quote Input'!B33>0), OR('Quote Input'!B22="Pressure-Treated Wood Rail", 'Quote Input'!B22="Cedar Wood Rail")), CEILING('Quote Input'!B33/6, 1)+1, 0) | C37: each | D37: =INDEX('Pricing DB'!$D$140:$D$167, MATCH("kdat_4x4x8", 'Pricing DB'!$A$140:$A$167, 0)) | E37: =B37*D37 | F37: Wood rail post every 6 ft; PT used even on cedar rail systems
A38: Feeney CableRail 10 ft kit | B38: =IF(AND(AND(INDEX('Project Type Behavior'!$E$4:$E$10, MATCH('Quote Input'!B13, 'Project Type Behavior'!$A$4:$A$10, 0))<>"N", 'Quote Input'!B33>0), 'Quote Input'!B22="Cable Railing"), CEILING('Quote Input'!B33/10, 1), 0) | C38: kit | D38: =INDEX('Pricing DB'!$D$140:$D$167, MATCH("cable_rail_kit_10ft", 'Pricing DB'!$A$140:$A$167, 0)) | E38: =B38*D38 | F38: 10 ft cable assembly + tensioners; need wood posts (see row 37)
A39: Tempered glass railing panel 36" x 42" | B39: =IF(AND(AND(INDEX('Project Type Behavior'!$E$4:$E$10, MATCH('Quote Input'!B13, 'Project Type Behavior'!$A$4:$A$10, 0))<>"N", 'Quote Input'!B33>0), 'Quote Input'!B22="Glass Panel"), CEILING('Quote Input'!B33/3, 1), 0) | C39: panel | D39: =INDEX('Pricing DB'!$D$140:$D$167, MATCH("glass_panel_36x42", 'Pricing DB'!$A$140:$A$167, 0)) | E39: =B39*D39 | F39: 3 ft panels with aluminum posts every 3 ft
A40: Aluminum glass-railing post + clamp set | B40: =IF(AND(AND(INDEX('Project Type Behavior'!$E$4:$E$10, MATCH('Quote Input'!B13, 'Project Type Behavior'!$A$4:$A$10, 0))<>"N", 'Quote Input'!B33>0), 'Quote Input'!B22="Glass Panel"), CEILING('Quote Input'!B33/3, 1)+1, 0) | C40: kit | D40: =INDEX('Pricing DB'!$D$140:$D$167, MATCH("alum_glass_post", 'Pricing DB'!$A$140:$A$167, 0)) | E40: =B40*D40 | F40: One per panel edge + 1 for the end
A42: Stairs (only if stair runs > 0)
A43: Item | B43: Qty | C43: Unit | D43: Unit Cost | E43: Line Cost | F43: Notes
A44: KDAT PT 2x10x16 (stair stringers, cut from blanks) | B44: =IF(AND(INDEX('Project Type Behavior'!$F$4:$F$10, MATCH('Quote Input'!B13, 'Project Type Behavior'!$A$4:$A$10, 0))<>"N", 'Quote Input'!B35>0), 'Quote Input'!B35*2, 0) | C44: each | D44: =INDEX('Pricing DB'!$D$140:$D$167, MATCH("kdat_2x10x16", 'Pricing DB'!$A$140:$A$167, 0)) | E44: =B44*D44 | F44: 2 stringers per stair run; cut from 16 ft blank
A45: ="Tread board: "&'Quote Input'!B21 | B45: =IF(AND(INDEX('Project Type Behavior'!$F$4:$F$10, MATCH('Quote Input'!B13, 'Project Type Behavior'!$A$4:$A$10, 0))<>"N", 'Quote Input'!B35>0), CEILING('Quote Input'!B36/2, 1), 0) | C45: each | D45: =IFERROR(INDEX('Pricing DB'!$C$7:$C$19, MATCH('Quote Input'!B21, 'Pricing DB'!$A$7:$A$19, 0))*7.33, 0) | E45: =B45*D45 | F45: 2 tread pieces per board (16 ft cut into 4 x 4 ft pieces, used as 2 treads)
A46: KDAT PT 1x8 riser stock (or matching deck material) | B46: =IF(AND(INDEX('Project Type Behavior'!$F$4:$F$10, MATCH('Quote Input'!B13, 'Project Type Behavior'!$A$4:$A$10, 0))<>"N", 'Quote Input'!B35>0), CEILING('Quote Input'!B36/2, 1), 0) | C46: each | D46: =INDEX('Pricing DB'!$D$140:$D$167, MATCH("kdat_2x10x16", 'Pricing DB'!$A$140:$A$167, 0))*0.5 | E46: =B46*D46 | F46: Vertical face of each stair; cut from 16 ft stock
...

Sheet Estimate Summary
A1: Estimate Summary
A2: Three-tier comparison for new-deck projects. Single-tier summary for stain/repair jobs.
A4: Project
A5: Client | B5: ='Quote Input'!B7
A6: Address | B6: ='Quote Input'!B8
A7: Project Type | B7: ='Quote Input'!B13
A8: Deck SF | B8: ='Quote Input'!B18
A9: Selected Decking | B9: ='Quote Input'!B21
A11: Three-Tier Decking Comparison (composite only)
A12: Decking | B12: Decking $/SF | C12: Waste | D12: Base Package | E12: Adders (shared) | F12: Subtotal | G12: Sell Price | H12: Range
A13: Trex Enhance | B13: =IFERROR(INDEX('Pricing DB'!$B$7:$B$19, MATCH("Trex Enhance", 'Pricing DB'!$A$7:$A$19, 0)), 0) | C13: =IFERROR(INDEX('Pricing DB'!$D$7:$D$19, MATCH("Trex Enhance", 'Pricing DB'!$A$7:$A$19, 0)), 0) | D13: ='Quote Input'!B18*(IF(INDEX('Project Type Behavior'!$C$4:$C$10, MATCH('Quote Input'!B13, 'Project Type Behavior'!$A$4:$A$10, 0))="Y", 'Quote Input'!E7, 0) + IF(INDEX('Project Type Behavior'!$D$4:$D$10, MATCH('Quote Input'!B13, 'Project Type Behavior'!$A$4:$A$10, 0))="Y", IFERROR(INDEX('Pricing DB'!$B$7:$B$19, MATCH("Trex Enhance", 'Pricing DB'!$A$7:$A$19, 0)), 0)*(1+IFERROR(INDEX('Pricing DB'!$D$7:$D$19, MATCH("Trex Enhance", 'Pricing DB'!$A$7:$A$19, 0)), 0)), 0))*'Quote Input'!E17 | E13: =('Quote Input'!E21+'Quote Input'!E22+'Quote Input'!E23+'Quote Input'!E24+'Quote Input'!E25+'Quote Input'!E26+'Quote Input'!E27+'Quote Input'!E28+'Quote Input'!E29+'Quote Input'!E30+'Quote Input'!E31+'Quote Input'!E32+'Quote Input'!E33+'Quote Input'!E34+'Quote Input'!E35+'Quote Input'!E36) | F13: =D13+E13 | G13: =F13/(1-'Quote Input'!B64) | H13: =TEXT(G13*(1-'Quote Input'!B65),"$#,##0")&" - "&TEXT(G13*(1+'Quote Input'!B65),"$#,##0")
A14: Trex Select | B14: =IFERROR(INDEX('Pricing DB'!$B$7:$B$19, MATCH("Trex Select", 'Pricing DB'!$A$7:$A$19, 0)), 0) | C14: =IFERROR(INDEX('Pricing DB'!$D$7:$D$19, MATCH("Trex Select", 'Pricing DB'!$A$7:$A$19, 0)), 0) | D14: ='Quote Input'!B18*(IF(INDEX('Project Type Behavior'!$C$4:$C$10, MATCH('Quote Input'!B13, 'Project Type Behavior'!$A$4:$A$10, 0))="Y", 'Quote Input'!E7, 0) + IF(INDEX('Project Type Behavior'!$D$4:$D$10, MATCH('Quote Input'!B13, 'Project Type Behavior'!$A$4:$A$10, 0))="Y", IFERROR(INDEX('Pricing DB'!$B$7:$B$19, MATCH("Trex Select", 'Pricing DB'!$A$7:$A$19, 0)), 0)*(1+IFERROR(INDEX('Pricing DB'!$D$7:$D$19, MATCH("Trex Select", 'Pricing DB'!$A$7:$A$19, 0)), 0)), 0))*'Quote Input'!E17 | E14: =('Quote Input'!E21+'Quote Input'!E22+'Quote Input'!E23+'Quote Input'!E24+'Quote Input'!E25+'Quote Input'!E26+'Quote Input'!E27+'Quote Input'!E28+'Quote Input'!E29+'Quote Input'!E30+'Quote Input'!E31+'Quote Input'!E32+'Quote Input'!E33+'Quote Input'!E34+'Quote Input'!E35+'Quote Input'!E36) | F14: =D14+E14 | G14: =F14/(1-'Quote Input'!B64) | H14: =TEXT(G14*(1-'Quote Input'!B65),"$#,##0")&" - "&TEXT(G14*(1+'Quote Input'!B65),"$#,##0")
A15: Trex Transcend | B15: =IFERROR(INDEX('Pricing DB'!$B$7:$B$19, MATCH("Trex Transcend", 'Pricing DB'!$A$7:$A$19, 0)), 0) | C15: =IFERROR(INDEX('Pricing DB'!$D$7:$D$19, MATCH("Trex Transcend", 'Pricing DB'!$A$7:$A$19, 0)), 0) | D15: ='Quote Input'!B18*(IF(INDEX('Project Type Behavior'!$C$4:$C$10, MATCH('Quote Input'!B13, 'Project Type Behavior'!$A$4:$A$10, 0))="Y", 'Quote Input'!E7, 0) + IF(INDEX('Project Type Behavior'!$D$4:$D$10, MATCH('Quote Input'!B13, 'Project Type Behavior'!$A$4:$A$10, 0))="Y", IFERROR(INDEX('Pricing DB'!$B$7:$B$19, MATCH("Trex Transcend", 'Pricing DB'!$A$7:$A$19, 0)), 0)*(1+IFERROR(INDEX('Pricing DB'!$D$7:$D$19, MATCH("Trex Transcend", 'Pricing DB'!$A$7:$A$19, 0)), 0)), 0))*'Quote Input'!E17 | E15: =('Quote Input'!E21+'Quote Input'!E22+'Quote Input'!E23+'Quote Input'!E24+'Quote Input'!E25+'Quote Input'!E26+'Quote Input'!E27+'Quote Input'!E28+'Quote Input'!E29+'Quote Input'!E30+'Quote Input'!E31+'Quote Input'!E32+'Quote Input'!E33+'Quote Input'!E34+'Quote Input'!E35+'Quote Input'!E36) | F15: =D15+E15 | G15: =F15/(1-'Quote Input'!B64) | H15: =TEXT(G15*(1-'Quote Input'!B65),"$#,##0")&" - "&TEXT(G15*(1+'Quote Input'!B65),"$#,##0")
A17: Selected Quote (from Quote Input)
A18: Sell Price | B18: ='Quote Input'!E40
A19: Range | B19: =TEXT('Quote Input'!E41,"$#,##0")&" - "&TEXT('Quote Input'!E42,"$#,##0")
A20: Subtotal Cost | B20: ='Quote Input'!E37
A21: Margin | B21: ='Quote Input'!B64

Sheet Client Range
A1: Client-Facing Preliminary Range
A2: Copy/paste the block below into a proposal email. All values reference Quote Input live.
A4: Proposal Block
A5: ="Dear "&'Quote Input'!B7&","&CHAR(10)&CHAR(10)&"Thank you for the opportunity to quote your deck project. "&"Based on the project scope at "&'Quote Input'!B8&", "&"we estimate your preliminary investment range at:"&CHAR(10)&CHAR(10)&TEXT('Quote Input'!E41,"$#,##0")&" - "&TEXT('Quote Input'!E42,"$#,##0")&CHAR(10)&CHAR(10)&"Project type: "&'Quote Input'!B13&CHAR(10)&"Approximate size: "&'Quote Input'!B18&" sq ft"&CHAR(10)&"Decking: "&'Quote Input'!B21&CHAR(10)&"Railing: "&'Quote Input'!B22&CHAR(10)&CHAR(10)&"This is a preliminary range based on stated scope. A firm fixed-"&"price quote will follow site inspection and final scope review. "&"Pricing assumes standard site access and conditions; engineering, "&"permits, and unusual site conditions may adjust final pricing."&CHAR(10)&CHAR(10)&"James Slogar, Owner"&CHAR(10)&"Central Wisconsin Deck Builders, LLC"&CHAR(10)&"(715) 544-7941 · cwdeckbuilders.com"

Sheet Scope Builder
A1: Scope Boilerplate by Project Type
A2: Standard scope, included, and excluded items by project type. Copy into your client proposal as appropriate.
A4: Stain Only
A5: Scope of Work | B5: Wash, sand rough spots, set raised fasteners, apply selected stain product to deck floor, railings, and stairs as specified. Move and protect homeowner furniture; cover landscaping and siding. Final touch-ups and full job-site cleanup.
A6: Included | B6: All materials (stain, brushes, rollers, pads, sandpaper, drop cloths, masking). All labor. Site protection. 1-year limited workmanship warranty against premature finish failure.
A7: Not Included | B7: Repair or replacement of damaged or rotted boards. Hardware replacement beyond setting existing fasteners. Structural repairs. Refinishing of pergolas, gazebos, or attached fences unless added in writing.
A9: Stain + Minor Repairs
A10: Scope of Work | B10: Stain Only scope plus targeted repairs: replace damaged deck boards (count specified), sister or repair compromised joists (LF specified), replace failed hardware as needed. Repairs completed before staining.
A11: Included | B11: Stain Only includes plus: repair-grade replacement boards, joist sister lumber, fasteners, hidden hardware as needed. Labor for repairs included. Same 1-year workmanship warranty.
A12: Not Included | B12: Wholesale frame replacement (use Frame + Deck Rebuild). New footings. Code upgrades beyond the repair scope.
A14: Resurface (Boards Only)
A15: Scope of Work | B15: Remove existing deck boards. Inspect frame for soundness (replace failed joists/beams as flagged). Install new deck boards in selected material with hidden fasteners. Refresh railings and stairs as elected.
A16: Included | B16: All new decking material, hidden fasteners, fascia (if specified). Frame inspection allowance. Labor for tear-off and install. Cleanup and disposal of old boards. 5-year workmanship warranty on new boards.
A17: Not Included | B17: Major frame replacement (quoted separately if uncovered during inspection). New footings. Code-driven structural upgrades.
A19: Frame + Deck Rebuild (Keep Footings)
A20: Scope of Work | B20: Remove existing deck and frame down to footings. Inspect footings for soundness. Build new code-compliant frame with selected framing material. Install new deck boards, railings, stairs, and fascia in selected materials.
A21: Included | B21: All new framing material (joists, beams, ledger, hangers, hardware). All new decking, railings, stairs. Permit and engineering allowance. Demo and disposal. 10-year workmanship warranty on structure.
A22: Not Included | B22: New footings (quoted separately if uncovered as inadequate during inspection). Landscape restoration beyond the deck footprint. Electrical, plumbing, or hot tub utility hookups.
A24: Full Tear-Out + New Build
A25: Scope of Work | B25: Complete demolition of existing deck, frame, and footings. Layout and install new code-compliant footings. Build new frame, deck, railings, stairs, and fascia in selected materials. Final inspection and homeowner walkthrough.
A26: Included | B26: Permit and engineering allowance. All footings, framing, decking, railings, stairs. Demo and full disposal. Site protection. Final walkthrough. 10-year workmanship warranty on structure. Manufacturer warranties pass through on decking and railing.
A27: Not Included | B27: Landscape restoration beyond the deck footprint. Electrical, plumbing, or hot tub utility hookups. Pergolas, screens, or outdoor kitchens unless added in writing.

Sheet Notes
A1: Notes & Usage Guide
A3: As-of date: 2026-05-28
A4: Schema version: 1.0
A5: Source data: sales/estimating/pricing-db.json
A6: Regenerate workbook: python build_estimator_workbook.py
A8: How to use
A9: 1.: Open the Quote Input sheet. Fill yellow cells from top to bottom.
A10: 2.: Select Project Type first. The engine adjusts what gets included/excluded based on the matrix in 'Project Type Behavior'.
A11: 3.: The big sell price at the top of Quote Input updates live as you edit inputs.
A12: 4.: For client proposals, copy the formatted block from the 'Client Range' sheet.
A13: 5.: For scope language by project type, use 'Scope Builder' to copy the appropriate blocks.
A15: Pricing updates
... A27: Waste applied to decking only: John applied waste % to combined framing+decking. CWDB v1 applies waste only to decking material (framing is precise; no waste).
